<?xml version="1.0"?>
<robot xmlns:xacro="http://wiki.ros.org/xacro">
  <xacro:macro name="galil">
    <xacro:include filename="$(find galil_description)/urdf/materials.xacro" />

    <link name="base_link">
      <visual>
	<origin xyz="0 0 0" rpy="0 0 0"/>
	<geometry>
	  <mesh filename="package://galil_description/meshes/base_link.stl"/>
	</geometry>
	<material name="silver"/>
      </visual>
    </link>

    <link name="needle_link">
      <visual>
	<geometry>
	  <mesh filename="package://galil_description/meshes/needle_link.stl"/>
	</geometry>
	<material name="silver"/>
      </visual>
    </link>
    
    <link name="vertical_link">
      <visual>
	<geometry>
	  <mesh filename="package://galil_description/meshes/vertical_link.stl"/>
	</geometry>
	<material name="silver"/>
      </visual>
    </link>
    
    <link name="horizontal_link">
      <visual>
	<geometry>
	  <mesh filename="package://galil_description/meshes/horizontal_link.stl"/>
	</geometry>
	<material name="silver"/>
      </visual>
    </link>
    
    <joint name="insertion_joint" type="prismatic">
      <origin xyz="0 0 0" rpy="0 0 0"/>
      <parent link="horizontal_link"/>
      <child link="needle_link"/>
      <axis xyz="-1.0 0.0 0.0"/>
      <limit upper="0.1" lower="0.0" effort="100" velocity="100"/>
    </joint>
    
    <joint name="horizontal_joint" type="prismatic">
      <origin xyz="0 0 0" rpy="0 0 0"/>
      <parent link="vertical_link"/>
      <child link="horizontal_link"/>
      <axis xyz="0.0 1.0 0.0"/>
      <limit upper="0.03" lower="-0.03" effort="100" velocity="100"/>
    </joint>
    
    <joint name="vertical_joint" type="prismatic">
      <origin xyz="0 0 0" rpy="0 0 0"/>
      <parent link="base_link"/>
      <child link="vertical_link"/>
      <axis xyz="0.0 0.0 1.0"/>
      <limit upper="0.05" lower="0.0" effort="100" velocity="100"/>
    </joint>

  </xacro:macro>

</robot>
